Workbook

Sheet S1 Q1 - rough notes
A1: Stage | B1: Accounts | C1: Conversion | D1: Basis / note
A2: LeadGen | B2: 1620 | D2: Starting cohort
A3: LeadDev | B3: 1164 | C3: =B3/B2 -> 0.71851852 | D3: Of LeadGen
A4: Sales | B4: 260 | D4: SSF skips the Sales stage.
A5: Onboarding | B5: 960 | C5: =B5/B3 -> 0.82474227 | D5: 82.5% of LeadDev across both motions.
A6: Adoption | B6: 424 | C6: =B6/B5 -> 0.44166667 | D6: Of Onboarding
A7: Expansion | B7: 89 | C7: =B7/B6 -> 0.20990566 | D7: Of Adoption
A9: Not reaching adoption | B9: =B5-B6 -> 536 | C9: =B9/B5 -> 0.55833333 | D9: Of onboarded accounts
A11: Question | B11: Read Table 1 on its own first. What's your read on the health of this funnel? Where's the biggest problem, and how confident are you?
A12: Main issue | B12: 536 of 960 onboarded accounts didn't reach Adoption (55.8%).
A13: Other concern | B13: Expansion converted 21.0%; the 90-day window may be too short.
A14: Confidence | B14: High in the numbers, moderate in the diagnosis.
A15: Next check | B15: Compare SSF and Sales-led results with stage targets.

Sheet S1 Q2 - motion split
A1: Stage | B1: SSF accounts | C1: Sales-led accounts | D1: SSF conversion | E1: Sales-led conversion
A2: LeadGen | B2: 1200 | C2: 420
A3: LeadDev | B3: 864 | C3: 300 | D3: =B3/B2 -> 0.72 | E3: =C3/C2 -> 0.71428571
A4: Sales | C4: 260 | E4: =C4/C3 -> 0.86666667
A5: Sales → Onboarding rate | E5: =C6/C4 -> 0.83076923
A6: Onboarding | B6: 744 | C6: 216 | D6: =B6/B3 -> 0.86111111 | E6: =C6/C3 -> 0.72
A7: Adoption | B7: 305 | C7: 119 | D7: =B7/B6 -> 0.40994624 | E7: =C7/C6 -> 0.55092593
A8: Expansion | B8: 38 | C8: 51 | D8: =B8/B7 -> 0.12459016 | E8: =C8/C7 -> 0.42857143
A9: Not reaching adoption | B9: =B6-B7 -> 439 | C9: =C6-C7 -> 97
A10: Share of non-adopters | B10: =B9/SUM(B9:C9) -> 0.81902985 | C10: =C9/SUM(B9:C9) -> 0.18097015
A11: Adoption rate gap (pp) | B11: =ROUND((E7-D7)*100,1) -> 14.1
A12: SSF share of onboarding | B12: =B6/SUM(B6:C6) -> 0.775
A13: Question | B13: Now use Table 2. Does your answer change? Show the specific numbers that drive your conclusion. (You'll need to compute conversion rates the tables don't give you.)
A14: First check | B14: LeadGen → LeadDev: SSF 72.0%, Sales-led 71.4%.
A15: Main finding | B15: SSF Adoption 41.0% vs Sales-led 55.1% (14.1 pp lower).
A16: Size matters | B16: SSF is 77.5% of onboarded accounts and 81.9% of non-adopters.
A17: What we don't know | B17: Customer mix or support may explain the difference; the data doesn't prove why.

Sheet S1 Q3 - rough notes
A1: Section 1 - Q3 | rough notes
A2: Question | B2: One motion has no Sales row. What does that structural difference imply, if anything, for what happens to those accounts later?
A3: Different journeys | B3: SSF skips Sales; Sales-led involves Sales or a partner and has a CSx owner from onboarding.
A4: Possible effect | B4: SSF may receive less human guidance during onboarding and adoption.
A5: What the numbers show | B5: Adoption: SSF 41.0% vs Sales-led 55.1%. Expansion: 12.5% vs 42.9%.
A6: What we can't prove | B6: The gap may also reflect differences in customers, intent, or Sales qualification.
A7: Bottom line | B7: The missing Sales stage may matter, but it's not proven to cause the gap.

Sheet S2 Q1 - Account A events
A1: Section 2 — Q1 | Account A checks
A2: Question | B2: The Account A timeline above was written by a person. Using only the raw event data, what would you compute to arrive at the same read — and what in the written timeline can you not actually derive from these events?
A3: Quick read | B3: Messaging stayed steady, while recorded advanced-feature actions faded before cancellation.
A4: Metric | B4: Value | C4: How I worked it out
A5: Account created (day) | B5: 0 | C5: account_created
A6: First campaign (day) | B6: 3 | C6: campaign_sent, first_campaign=true
A7: Activation lag (days) | B7: =B6-B5 -> 3 | C7: First campaign minus account_created
A8: Workflows created | B8: 3 | C8: workflow_created on days 4, 5, 7
A9: Last workflow edit (day) | B9: 19 | C9: workflow_edited on days 9, 14, 19
A10: AI agent runs (observed) | B10: 6 | C10: 4 runs day 10 + 2 runs day 12
A11: Last AI trigger (day) | B11: 12 | C11: Last ai_agent_triggered event in extract
A12: Subscription cancelled (day) | B12: 71 | C12: subscription_cancelled
A13: Days since last workflow edit | B13: =B12-B9 -> 52 | C13: 52 days from last edit to cancellation; not proof workflows stopped running.
A14: Days since last AI trigger | B14: =B12-B11 -> 59 | C14: 59 days from last recorded AI trigger; check whether tracking is complete.
A15: Sent messages / week (avg) | B15: =AVERAGE(C20:C29) -> 90.2 | C15: Average across 10 weekly records.
A16: Weekly sent (min–max) | B16: =MIN(C20:C29)&"–"&MAX(C20:C29) -> 88–93 | C16: Lowest and highest weekly sent message counts.
A18: Weekly messaging events
A19: Week | B19: Event day | C19: Sent | D19: Received
A20: 1 | B20: 0 | C20: 88 | D20: 184
A21: 2 | B21: 7 | C21: 91 | D21: 191
A22: 3 | B22: 14 | C22: 93 | D22: 195
A23: 4 | B23: 21 | C23: 90 | D23: 189
A24: 5 | B24: 28 | C24: 89 | D24: 186
A25: 6 | B25: 35 | C25: 92 | D25: 193
A26: 7 | B26: 42 | C26: 90 | D26: 189
A27: 8 | B27: 49 | C27: 91 | D27: 191
A28: 9 | B28: 56 | C28: 90 | D28: 189
A29: 10 | B29: 63 | C29: 88 | D29: 184
A31: Notes / limits
A32: Main observation | C32: Messaging stayed near 90/week; recorded workflow edits and AI triggers stopped appearing.
A33: Timing detail | C33: The third workflow was made on day 7, labelled week 2 in the data.
A34: Can't confirm | C34: Creating or editing workflows doesn't tell us if they kept running or added value.
A35: Can't confirm | C35: Product events don't tell us whether anyone checked in with the customer.
A36: Tracking check | C36: No AI triggers appear after day 12; confirm the event log is complete.
A37: Data check | C37: Week 1 summary is dated day 0. Check how weekly periods are recorded.

Sheet S2 Q2 - detection design
A1: Section 2 — Q2 | Early-warning detection
A2: Question | B2: These five accounts are representative of thousands. Design how you'd detect the accounts worth worrying about at that scale: what would you compute, where in the stack would each piece live, and how fresh would it need to be?
A3: Approach | B3: Daily workspace-level watchlist; clear reasons, not a black-box health score. Compare SSF and Sales-led accounts by age and plan.
A5: SIGNALS TO COMPUTE
A6: Signal | B6: How I'd calculate it | C6: Source | D6: Where it lives | E6: Refresh
A7: Activation | B7: Days from account_created to first campaign_sent. No campaign = not activated. | C7: Product events | D7: Warehouse workspace model | E7: Daily
A8: Depth features | B8: Distinct templates/workflows/agents created; AI runs; days since last relevant recorded event. Does not prove workflow execution. | C8: Product events | D8: Warehouse workspace model | E8: Daily
A9: Core messaging | B9: Last 2 weeks' sent and received messages vs previous 2 weeks; don't treat stable messaging alone as healthy. | C9: message_activity_weekly | D9: Warehouse workspace model | E9: Daily
A10: Engagement & CSx | B10: Lifecycle email interactions; CSx calls and follow-ups; owner and open concerns (when recorded in structured form). | C10: HubSpot / lifecycle history | D10: Warehouse joins on workspace ID | E10: Daily
A11: Commercial signals | B11: Paid plan, seats, upgrades, downgrades, cancellation and upcoming renewal. | C11: Chargebee / Stripe | D11: Warehouse; current billing state | E11: Hours / daily
A12: Data confidence | B12: Age of last valid event; source sync status; missing data should be 'Unknown', not assumed inactivity. | C12: Event freshness + Dagster runs | D12: Warehouse QA + orchestration | E12: Each sync
A14: PROCESS / SYSTEM HANDOFF
A15: Step | B15: What happens | C15: Tool(s) | D15: Freshness | E15: Why
A16: 1 — Collect | B16: Incrementally ingest events, customer context and subscription data into the warehouse. | C16: Airbyte → Warehouse | D16: Every few hours / daily | E16: Avoid expensive full resyncs
A17: 2 — Model | B17: Compute workspace signals; segment by motion, plan and lifecycle age; save status, reasons and as-of timestamp. | C17: Warehouse + Dagster | D17: Daily | E17: Stable, explainable scoring and QA
A18: 3 — Sync | B18: Write status, reasons and last updated back to the Workspace record. | C18: Hightouch → HubSpot | D18: Daily after model completes | E18: Actionable within existing CRM
A19: 4 — Respond | B19: Sales-led: CSx follow-up task. SSF: relevant lifecycle guidance or owned review queue. Slack only for urgent/high-priority cases. | C19: HubSpot + Make/n8n | D19: After each sync | E19: Different motion, appropriate next step
A20: Risk logic | B20: Test ~14 days without depth-feature adoption/activity as ONE candidate signal; combine with others. Calibrate thresholds to actual outcomes. | C20: Warehouse rules | D20: Daily | E20: Avoid false alarms from normal adoption patterns
A22: CHECK THE FIVE ACCOUNTS (ILLUSTRATIVE, NOT SCORED FROM A–E RAW EVENTS)
A23: Account | B23: Observed pattern | C23: Illustrative status | D23: Reason to check | E23: Guardrail
A24: A (SSF, 42 seats) | B24: Messaging steady (~90/wk); last workflow edit day 19, AI trigger day 12; cancelled day 71. | C24: At risk before cancellation | D24: Advanced-feature events faded. | E24: Workflow may still run; only observed events available
A25: B (SSF, 9 seats) | B25: Activated day 8; no template/workflow; light messaging; downgraded day 63. | C25: Watch before downgrade | D25: No depth-feature adoption observed. | E25: Don't use email opens alone
A26: C (SSF, 28 seats) | B26: Built templates, 5 workflows and active AI agents; expanded day 55. | C26: Healthy signal | D26: Strong adoption despite no human contact. | E26: Don't flag solely for no CSx
A27: D (Sales-led, 35 seats) | B27: CSx contact; templates week 1, workflow day 30, active AI day 41; expanded day 82. | C27: Healthy signal | D27: Progressing into depth features. | E27: Don't over-penalise slower but successful adoption
A28: E (Sales-led, 18 seats) | B28: CSx call flagged workflows; template only, no workflow usage; renewal flat, at risk. | C28: At risk / priority review | D28: Known adoption gap despite human contact. | E28: CSx notes are context, not proof of cause
A30: WORKED CHECK (ACCOUNT A RAW EVENTS ONLY)
A31: Metric | B31: Later day / input | C31: Earlier day / input | D31: Calculated result | E31: Meaning
A32: Last workflow edit → cancellation | B32: 71 | C32: 19 | D32: =B32-C32 -> 52 | E32: 52-day gap in editing, not proof workflows stopped
A33: Last AI trigger → cancellation | B33: 71 | C33: 12 | D33: =B33-C33 -> 59 | E33: 59-day gap in observed AI triggers
A34: Weekly messages range | B34: 88 | C34: 93 | D34: =C34-B34 -> 5 | E34: Only 5 messages from min to max across 10 weekly snapshots
A35: Illustrative inactivity watch day | B35: 19 | C35: 14 | D35: =B35+C35 -> 33 | E35: Day 33 would be a candidate check, not proof of inactivity
A37: Important limit | B37: Only Account A has underlying raw events here. B–E status examples come from the supplied narratives. A production rule needs validated tracking, time windows and outcomes.

Sheet S2 Q3 - event gaps
A1: Section 2 — Q3 | Event tracking priorities
A2: Question | B2: What's missing from this event schema — what would you instrument first, and what would you deliberately not bother capturing even though you could?
A3: Main gap | B3: Creation and edits don't show whether depth features ran or worked.
A5: INSTRUMENT FIRST — PRIORITISED
A6: Priority | B6: Event or signal | C6: Essential fields / source | D6: What it answers | E6: RevOps use
A7: P0 | B7: Workflow execution: success / failure | C7: workspace_id, workflow_id, run_id, occurred_at, status, error category | D7: Did the workflow actually run and succeed? | E7: Daily runs, last successful run, failures; prevent false inactivity flags
A8: P0 | B8: AI agent result: success / failure | C8: workspace_id, agent_id, run_id, occurred_at, status, error category (no transcripts) | D8: Did the agent produce a successful outcome, not just trigger? | E8: Successful runs and recent failures
A9: P0 | B9: Reliable event envelope | C9: event_id, workspace_id, occurred_at, ingested_at; stable feature_id and event version | D9: Can we join, deduplicate, and trust event timing? | E9: Protect daily risk signals from missing/delayed events
A10: P1 | B10: Template used | C10: workspace_id, template_id, occurred_at, use context | D10: Was a template actually used after creation? | E10: Adoption beyond one-time setup
A11: P1 | B11: Workflow / agent enabled, paused, or deleted | C11: workspace_id, feature_id, state, occurred_at | D11: Did someone intentionally disable a feature? | E11: Separate stopped features from unchanged-but-running features
A12: P1 | B12: Seat activation and usage | C12: workspace_id, user_id (pseudonymous), invited/accepted/active status, active day | D12: How many of the licensed users actually participate? | E12: Distinct active seats; important for a 42-seat workspace
A13: P1 | B13: Weekly message window | C13: workspace_id, period_start, period_end, sent_count, received_count | D13: What dates does week=1 refer to? | E13: Reliable messaging trend comparisons
A14: JOIN, DON'T DUPLICATE | B14: CSx touchpoints, lifecycle emails, plan and seats | C14: HubSpot / lifecycle source + Chargebee / Stripe joined by workspace | D14: What support or commercial change happened? | E14: Context for intervention and later outcomes
A16: DELIBERATELY SKIP
A17: Skip | B17: Every hover, click and routine page view | C17: Many events; little proof of value | D17: High noise and cost | E17: Not part of initial health model
A18: Skip | B18: Raw customer message bodies and contact content | C18: Sensitive personal data | D18: Privacy and access risk | E18: Use message counts/trends instead
A19: Skip | B19: Full AI conversation transcripts | C19: Sensitive, costly and not required for risk flagging | D19: Privacy / storage burden | E19: Track run status and outcomes instead
A21: ACCOUNT A — WHAT THIS CHANGES
A22: Observed | B22: Last workflow edit: day 19; last AI trigger: day 12; messaging ~90 sent/week.
A23: Unknown today | B23: Whether workflows were still running successfully; whether AI outcomes were useful; whether invited users adopted the product.
A24: Better test | B24: Compare recent successful workflow / AI runs and active seats with previous periods before flagging a customer as inactive.
A25: Caution | B25: New fields need consistent definitions, deduplication and validation; missing data should remain Unknown.

Sheet S3 Q1 - priorities
A1: Section 3 — Q1 | Prioritising lead qualification
A2: Question | B2: Based on what you've found so far, where does lead qualification sit relative to the other things you've seen?
A3: Sales concern | B3: Head of Sales says reps spend about half their day triaging poor-fit leads; this is an unverified claim, not a measured result.
A5: WHAT THE FUNNEL SHOWS
A6: Metric | B6: Value | C6: Why it matters
A7: Onboarded accounts | B7: ='S1 Q1 - rough notes'!B5 -> 960 | C7: Combined cohort
A8: Accounts not reaching Adoption | B8: ='S1 Q1 - rough notes'!B9 -> 536 | C8: Largest absolute loss after onboarding
A9: Non-adoption share | B9: ='S1 Q1 - rough notes'!C9 -> 0.55833333 | C9: More than half don't progress
A10: SSF Adoption rate | B10: ='S1 Q2 - motion split'!D7 -> 0.40994624 | C10: SSF has no Sales stage; fixing rep qualification cannot directly fix this path
A11: Sales-led Adoption rate | B11: ='S1 Q2 - motion split'!E7 -> 0.55092593 | C11: Higher than SSF; doesn't prove support causes the difference
A12: SSF share of non-adopters | B12: ='S1 Q2 - motion split'!B10 -> 0.81902985 | C12: Most of the count comes from self-signup
A13: SSF LeadGen → LeadDev | B13: ='S1 Q2 - motion split'!D3 -> 0.72 | C13: Comparable top-of-funnel conversion, not a lead-quality measure
A14: Sales-led LeadGen → LeadDev | B14: ='S1 Q2 - motion split'!E3 -> 0.71428571 | C14: Conversion alone cannot tell us lead fit or rep effort
A16: HOW I'D HANDLE THE SALES CONCERN
A17: Check | B17: What I'd look at | C17: Why
A18: Lead sources + quality | B18: Disqualified lead share by source, reason, ICP fit and outcome | C18: Identify whether a few sources create most wasted effort
A19: Rep time + routing | B19: Minutes spent triaging, speed to first action, duplicates, routing misses | C19: Measure true time cost before rebuilding qualification
A20: Downstream outcomes | B20: Qualified → opportunity/closed-won, onboarding and adoption by lead source | C20: See whether qualification improves actual customer results
A21: Practical next move | B21: Run a focused audit while investigating adoption and early churn risk | C21: Keep the decision evidence-led; reprioritise if Sales impact proves larger
A23: BOTTOM LINE | B23: Adoption has the clearest measured leak. Lead quality remains a credible hypothesis worth validating quickly, not a proven root cause.

Sheet S3 Q2 - quarter plan
A1: Section 3 — Q2 | First-quarter plan
A2: Question | B2: You can't work on everything at once. Lay out your actual priority order for your first quarter, and justify why qualification lands where it does.
A3: Decision | B3: Start with the measured adoption leak; investigate Sales lead quality immediately, but only build a bigger qualification solution once its impact is proven.
A5: FIRST-QUARTER ROADMAP
A6: Order | B6: Timing | C6: Focus | D6: Deliverable | E6: How I'd judge it
A7: 1 | B7: Weeks 1–2 | C7: Validate adoption and lead-quality problems | D7: Funnel baseline, event-quality checks; quick rep-time/lead-routing audit | E7: Reliable baseline; evidence of Sales effort, bad leads and source mix
A8: 2 | B8: Weeks 3–6 | C8: Ship adoption-risk pilot | D8: Workflow/AI execution signals; daily SSF watchlist with reasons | E8: Usable account flags and acceptable false-alert rate
A9: 3 | B9: Weeks 7–9 | C9: Test targeted intervention | D9: SSF guidance and CSx tasks for Sales-led accounts | E9: Adoption/feature-use change versus comparison group; actionable follow-ups
A10: 4 | B10: Weeks 10–12 | C10: Fix proven qualification issues | D10: Targeted routing/deduplication/source-quality fix, not a CRM rebuild | E10: Minutes saved per lead and qualified-to-outcome performance
A12: WHY ADOPTION IS FIRST
A13: Metric | B13: Value | C13: Meaning
A14: Onboarded accounts | B14: ='S1 Q1 - rough notes'!B5 -> 960 | C14: Monthly cohort
A15: Not reaching Adoption | B15: ='S1 Q1 - rough notes'!B9 -> 536 | C15: Biggest absolute loss across onboarding → adoption
A16: Share not reaching Adoption | B16: ='S1 Q1 - rough notes'!C9 -> 0.55833333 | C16: Measured leak, not merely a complaint
A17: SSF adoption rate | B17: ='S1 Q2 - motion split'!D7 -> 0.40994624 | C17: SSF never goes through Sales
A18: Sales-led adoption rate | B18: ='S1 Q2 - motion split'!E7 -> 0.55092593 | C18: Benchmark for a different customer journey
A20: LEAD QUALITY — TEST EARLY, BUILD IF JUSTIFIED
A21: Question | B21: Check | C21: Decision
A22: Is the time cost real? | B22: Sample triage time by rep; duplicates and routing delays; quantify hours lost | C22: Fix quick, obvious problems early
A23: Are certain sources low quality? | B23: Source, ICP match, disqualification reason and cost per qualified opportunity | C23: Focus on worst sources rather than changing all lead scoring
A24: Does qualification change outcomes? | B24: Qualified → opportunity → win → onboarding and adoption by source | C24: Expand only if downstream outcomes justify it
A25: When would I re-order? | B25: Sales time loss and revenue impact clearly exceed the adoption pilot opportunity | C25: Move qualification fixes forward
A27: WHAT SUCCESS LOOKS LIKE
A28: Adoption work | B28: A working pilot with trusted signals, documented actions and a measured change in adoption or feature use
A29: Qualification work | B29: Measured rep time saved and evidence of improved lead outcomes
A30: Reality check | B30: Data only proves the adoption drop; Head of Sales's 'half the day' estimate needs validation. The two efforts need not be mutually exclusive.

Sheet S3 Q3 - Sales response
A1: Section 3 — Q3 | Sales conversation + commitments
A2: Question | B2: How do you respond to the Head of Sales, and what do you commit to?
A3: Approach | B3: Acknowledge the Sales pain, commit to a two-week diagnosis, and avoid promising an unproven full qualification rebuild.
A5: MY RESPONSE TO THE HEAD OF SALES
A6: Acknowledge | B6: If reps are spending half their day sorting poor-fit leads, that's worth investigating.
A7: Offer | B7: I'll own a focused review and bring you findings and recommended changes within two weeks.
A8: Explain the trade-off | B8: The measured adoption drop also needs work, especially for SSF accounts. We should prioritise based on business impact.
A10: EXACT COMMITMENTS
A11: When | B11: What I'd do | C11: Output | D11: Measure | E11: Why
A12: Week 1 | B12: Meet with a small sample of reps; inspect representative recent leads, disqualification reasons, sources and routing. | C12: Baseline of actual qualification issues and rep time lost. | D12: Sampled triage minutes per lead; duplicates; misroutes. | E12: Validate the claimed time cost.
A13: Week 1 | B13: Identify easy fixes as soon as they're proven; coordinate with Sales before changing rules. | C13: One quick fix if warranted (e.g., duplicate prevention or routing). | D13: Change in duplicates or incorrectly assigned leads. | E13: Don't wait for a full project to remove clear friction.
A14: By end of week 2 | B14: Share findings with Head of Sales; rank fixes by time saved and downstream opportunity impact. | C14: One-page recommendation and agreed next step. | D14: Time spent triaging; share disqualified; qualified → opportunity. | E14: Close the loop and make a measured decision.
A15: After the first fix | B15: Review outcomes with Sales; monitor whether the change actually helps. | C15: Keep, refine, or roll back the fix. | D15: Rep time saved; qualified-to-opportunity rate. | E15: Avoid declaring victory from process changes alone.
A17: THE CONTEXT I WOULD EXPLAIN
A18: Metric | B18: Value | C18: Why it matters
A19: Onboarding → Adoption | B19: ='S1 Q1 - rough notes'!C6 -> 0.44166667 | C19: 44.2% reach adoption in blended cohort; biggest absolute leak.
A20: SSF Onboarding → Adoption | B20: ='S1 Q2 - motion split'!D7 -> 0.40994624 | C20: 41.0%; improving Sales qualification can't directly fix the self-signup journey.
A21: Sales triage time claim | B21: Unverified (Head of Sales estimate) | C21: Measure the time cost before committing to a rebuild.
A23: WHAT I'D NOT PROMISE | B23: An immediate full qualification overhaul, guaranteed higher lead quality, or that lead quality causes the adoption drop.

Sheet S4 - architecture + MVP
A1: SECTION 4 | SYSTEM DESIGN + TWO-WEEK MVP
A2: Task | B2: Design the end-to-end early-warning system. Show an actual diagram, precise signals, data movement and timing, actions, validation, trade-offs and first two-week build.
A3: Deliverables | B3: Diagram embedded in the Google Doc, with standalone PNG and SVG; this tab documents the logic, proposed schedules and pilot gates.
A5: BUSINESS OBJECTIVE — BENCHMARK AND PROPOSED TARGET
A6: Metric | B6: Value | C6: Basis / meaning | D6: Type | E6: Why it matters
A7: SSF adoption baseline | B7: ='S1 Q2 - motion split'!D7 -> 0.40994624 | C7: 305 / 744 from Section 1 | D7: Observed | E7: Main segment to improve
A8: Proposed SSF adoption target | B8: 0.46 | C8: 90-day onboarding → adoption, +5 pp experiment target | D8: Hypothesis | E8: Not a forecast or promised outcome
A9: Target improvement (pp) | B9: =(B8-B7)*100 -> 5.0053763 | C9: 46% minus 41% = approx. 5 percentage points | D9: Calculated | E9: Measure against a comparable/holdout cohort
A10: Sales-led baseline | B10: ='S1 Q2 - motion split'!E7 -> 0.55092593 | C10: 119 / 216 | D10: Observed | E10: Different journey; not a causal comparator
A11: A example watch day | B11: =19+14 -> 33 | C11: Last depth-feature edit day 19 + candidate 14-day gap | D11: Hypothetical | E11: Only based on observed actions, not actual run state
A12: Days before A cancellation | B12: =71-B11 -> 38 | C12: 71 - candidate day 33 | D12: Hypothetical | E12: Potential lead time, not a proven alert
A14: THE SIGNAL — WORKSPACE + AS-OF DATE
A15: Signal / field | B15: Definition / calculation | C15: Source | D15: Owner | E15: Confidence rule
A16: activation_lag_days | B16: First campaign_sent day - account_created day; null if no campaign | C16: Product events | D16: Warehouse | E16: First campaign event is Superchat's Activated definition
A17: depth_setup_counts | B17: Distinct templates, workflows and agents created | C17: Product events | D17: Warehouse | E17: Creation is not proof of useful adoption
A18: depth_success_14d | B18: Successful workflow and AI runs in last 14 days (requires proposed event instrumentation) | C18: Product events (new events) | D18: Warehouse | E18: If execution events are missing, usage is UNKNOWN, not zero. Never substitute workflow edits.
A19: depth_last_success_at | B19: Most recent confirmed successful workflow/AI execution timestamp | C19: Product events (new events) | D19: Warehouse | E19: Null last-success timestamp from unavailable telemetry is UNKNOWN, not an inactivity alert.
A20: core_msg_14d_delta | B20: 14-day sent/received versus previous 14 days; account and motion context | C20: Product weekly snapshots | D20: Warehouse | E20: Steady volume alone doesn't prove health; check bucket dates
A21: seat_activation | B21: Distinct active licensed users / seats, with verified user identity | C21: Product seats/users | D21: Warehouse | E21: Never sum invites without event definition
A22: commercial_state | B22: Paid status, current plan/seats, renewal/downgrade/cancellation events | C22: Chargebee subscriptions; Stripe payment evidence only | D22: Warehouse | E22: Chargebee is authoritative for paid status; never count Stripe as another subscription.
A23: touchpoints | B23: CSx owner/last call, completed tasks and lifecycle engagement | C23: HubSpot + lifecycle data | D23: Warehouse | E23: Contact history missing ≠ no check-in
A24: quality_flag | B24: Freshness, stable workspace_id, deduplicated event_id, model version | C24: Raw + Dagster QA | D24: Warehouse | E24: UNKNOWN if data late or join invalid
A26: DETERMINISTIC RISK RULES — PILOT, NOT PROVEN THRESHOLDS
A27: Tier | B27: Starting rule to test | C27: Action | D27: Suppress / exception | E27: Why
A28: WATCH | B28: With verified telemetry: no confirmed successful depth usage for a tested 14-day window after onboarding grace. Without it, 'reduced observed interaction' is human-review ONLY. | C28: Human review if proxy-only; outreach only when confirmed usage/risk evidence exists. | D28: Never turn missing executions or no edits into a claim of non-use. | E28: A provisional proxy is not an automated risk or outreach decision.
A29: AT RISK | B29: Reliable WATCH evidence plus an independent signal: repeated execution failures, material messaging decline, or verified downgrade intent. | C29: High-priority CSx / approved SSF outreach | D29: Evidence and current eligibility must be complete; deduplicate tasks/outreach. | E29: Reduce noisy single-metric alerts
A30: UNKNOWN | B30: Execution events unavailable, source stale, join failed or actor unknown; do not infer customer inactivity. | C30: Data-quality review and, separately, low-confidence interaction watchlist if useful. | D30: Never auto-message on an UNKNOWN/execution-gap-only proxy. | E30: Missing data isn't customer disengagement
A31: RECOVERED | B31: Confirmed successful depth activity sustained; no urgent open commercial signal | C31: Clear/snooze risk and close related task | D31: Cooldown/review actions | E31: Stop repeat alerts
A32: SCOPE | B32: Paid active workspaces only for pilot; compare SSF and Sales-led and account age | C32: Select owners / playbooks | D32: Exclude cancelled, opted-out, just contacted | E32: Reason codes + visible audit trail
A34: DATA FLOW + TIMING (PROPOSED)
A35: From | B35: Connection | C35: Destination | D35: Timing | E35: Contract / guardrail
A36: Product backend | B36: Existing product event feed | C36: Warehouse raw | D36: As received | E36: Do not create duplicate Airbyte product sync
A37: HubSpot + lifecycle interactions | B37: Airbyte incremental ingestion | C37: Warehouse raw | D37: Every 4 hours | E37: No expensive full resync; use verified IDs
A38: Chargebee (subscription) + Stripe (payments) | B38: Airbyte incremental ingestion | C38: Warehouse raw | D38: Every 4 hours | E38: Incremental IDs; Chargebee determines subscription state; Stripe is a payment signal, not another subscription.
A39: Dagster | B39: Orchestrate ingestion, QA and model runs | C39: Warehouse risk model | D39: Daily after sources pass QA | E39: On failure send technical Slack alert
A40: Warehouse model | B40: Hightouch reverse ETL on changed rows | C40: HubSpot Workspace object | D40: Daily after model success | E40: Sync status, reason, last depth success, as-of timestamp
A41: HubSpot Workspace risk property change | B41: HubSpot workflow / webhook → Make or n8n | C41: SSF / Sales-led action | D41: After valid property change | E41: Before action: recheck live eligibility and owner; idempotency = workspace_id + reason + 14-day cooldown.
A42: HubSpot actions + email response | B42: Airbyte incremental → warehouse | C42: Action feedback and evaluation | D42: Every 4 hours + daily model | E42: Avoid re-alerts, measure outcomes
A44: LAST MILE + LLM
A45: SSF action | B45: Approved feature-specific guidance ONLY from reliable risk evidence and live eligibility check. | C45: Owner: lifecycle | D45: Recheck paid/not cancelled, current status, opt-out and previous outreach immediately before sending. | E45: Suppress cancelled/recovered; one message per workspace + reason + cooldown window.
...

Sheet S5 Q1 - CRM gaps
A1: SECTION 5 — Q1 | CRM limitations
A2: Question | B2: Walk us through what our CRM can and can't answer about the accounts above. Be specific — which questions would a CS lead, a finance person, or Jonas ask that this structure handles badly?
A3: Important assumption | B3: The four Beauty Lounge workspaces appear related, but shared branding/contacts do NOT prove one legal entity or payer.
A5: EXAMPLE — FOUR BEAUTY LOUNGE WORKSPACES
A6: Workspace | B6: Plan | C6: Seats | D6: Motion | E6: Listed owner | F6: Primary contact
A7: Beauty Lounge Mitte | B7: Pro | C7: 8 | D7: self_signup | E7: — | F7: m.weber@beautylounge.de
A8: Beauty Lounge Charlottenburg | B8: Pro | C8: 6 | D8: self_signup | E8: — | F8: m.weber@beautylounge.de
A9: Beauty Lounge Spandau | B9: Starter | C9: 4 | D9: self_signup | E9: — | F9: s.krause@beautylounge.de
A10: Beauty Lounge GmbH | B10: Business | C10: 25 | D10: sales_led | E10: Jonas (AE) | F10: m.weber@beautylounge.de
A12: Number of workspaces | B12: =COUNTA(A7:A10) -> 4 | C12: Separate Workspace records; each has its own subscription.
A13: Licensed seats (sum) | B13: =SUM(C7:C10) -> 43 | C13: Seat licences, NOT a verified unique-user count or one legal customer's total.
A14: SSF seats (sum) | B14: =SUMIF(D7:D10,"self_signup",C7:C10) -> 18 | C14: Across the three SSF workspaces.
A15: Sales-led seats (sum) | B15: =SUMIF(D7:D10,"sales_led",C7:C10) -> 25 | C15: Jonas is shown as AE for GmbH, not necessarily the CSx owner.
A16: Same legal customer / payer? | B16: UNKNOWN | C16: Not determined from names, domain, or primary contacts.
A18: WHAT EACH STAKEHOLDER CAN AND CANNOT ANSWER
A19: Stakeholder | B19: Their real question | C19: What CRM helps with | D19: What's unreliable | E19: Why / needed check
A20: CS lead | B20: Which locations need help, and who's responsible? | C20: Workspace plan, seats, motion and named owner (where set). | D20: Group-wide health, consistent relationship owner, workspace-specific contact context. | E20: Workspace → Company links incomplete; a Contact can relate to several Users/Workspaces.
A21: Finance | B21: How much recurring revenue and renewal exposure does Beauty Lounge represent? | C21: Separate CB Subscription records where Workspace associations work. | D21: Consolidated revenue, common payer, legal parent, joint renewal/contract scope. | E21: No reliable corporate hierarchy; sample lacks price, payer and renewal fields.
A22: Jonas (AE) | B22: Are the three SSF sites tied to my 25-seat GmbH deal; is that expansion? | C22: GmbH Workspace is Sales-led with Jonas listed as AE. | D22: Which other Workspaces belong to his commercial relationship. | E22: Shared domain / contact do not prove a deal covers separate subscriptions.
A24: EXISTING CRM STRUCTURE — WHAT CAUSES THE GAP
A25: Workspace | B25: Real product workspace; sent from backend in real time. | C25: Use workspace_id as the reporting grain. | D25: Not itself a legal parent account.
A26: CB Subscription | B26: Billing subscription mirrors Chargebee; one per shown Workspace. | C26: Works when Workspace association is correct. | D26: Can't infer a shared payer across four subscriptions.
A27: User / Contact | B27: Users are workspace-specific; shared login can map multiple Users to one Contact. | C27: User and Contact remain distinct. | D27: Contact-only reports can mix workspace activity or double-count people.
A28: Company | B28: Business representation; manually or domain created. | C28: Workspace → Company association type exists. | D28: Not consistently populated; no parent/child hierarchy.
A29: Deal / Lead | B29: Deal represents Sales-led opportunity; Lead is prequalification. | C29: Jonas may use the GmbH Deal/Workspace. | D29: SSF workspaces have no Sales-led Deal; deal relation must be verified.
A31: BOTTOM LINE | B31: Workspace-level facts are usable. Cross-workspace reporting, revenue roll-ups and owner/action decisions require verified associations and group identity.
A32: NEXT DESIGN QUESTION | B32: Q2 will propose what changes, what stays and how to relate the objects; this sheet only describes current limitations.
A33: Other sampled SSF accounts | B33: Physio Nord Hamburg (Pro, 11 seats) and Café Milo (Starter, 3 seats) have visible Workspace-level facts but no verified group relationship.
A34: What we cannot assume | B34: Their names, primary contacts and workspace records do not establish a legal parent, shared bill-to Company, ownership of other workspaces or expansion scope.

Sheet S5 Q2 - CRM redesign
A1: SECTION 5 — Q2 | VERIFIED MULTI-WORKSPACE CRM MODEL
A2: Question | B2: Superchat is moving upmarket, and accounts like this will become more common, and bigger. Redesign the model: what changes, what stays, and why? Show the objects and how they relate.
A3: Design decision | B3: Keep existing HubSpot objects and Workspace as the product grain. Add verified operating, billing and buying relationships; no name/domain-based grouping.
A5: OBJECTS — WHAT STAYS, WHAT CHANGES
A6: Object | B6: Keep | C6: Change / add | D6: Identity / relationship | E6: Why
A7: Company | B7: Existing Company object; native parent-child capability | C7: Verify legal/operating hierarchy; optional group parent; explicit business associations | D7: HubSpot company ID; external legal/billing reference where available | E7: Group reporting without fictional mergers
A8: Workspace | B8: Existing backend-created product account, plan, seats, motion, risk fields | C8: Associate with verified operating Company; keep Workspace owner separate | D8: product workspace_id; usually one verified operating Company | E8: Exact account to target with Section 4 risk action
A9: CB Subscription | B9: Existing backend-created subscription mirror of Chargebee | C9: Associate the verified payer Company (which can differ from operator) and preserve subscription history; Chargebee remains authoritative. | D9: Chargebee subscription_id; authoritative Workspace link | E9: Chargebee is the billing source; associations join CRM records, not replace billing truth.
A10: User | B10: Existing one User per workspace membership | C10: Preserve User-to-Workspace and User-to-Contact links; verify login ID | D10: workspace_id + user_id; may share login ID across Workspaces | E10: Don't confuse person and membership
A11: Contact | B11: Existing real person record | C11: Keep one identity but do not use Contact as proof of Workspace ownership | D11: Contact ID / matched verified identity | E11: One person may work across many workspaces
A12: Deal | B12: Existing Sales-led opportunity only | C12: Associate buying Company and explicit in-scope Workspace(s); contract scope validated | D12: Deal ID; optional Workspace links | E12: Jonas's opportunity scope is not all shared contacts
A13: Lead | B13: Existing prequalification object | C13: Keep original routing/qualification workflows | D13: Existing Lead ↔ Contact/Company semantics | E13: Do not create Sales opportunity for all SSF
A15: RELATIONSHIPS — PROPOSED CARDINALITY AND TRUST
A16: From | B16: To | C16: Cardinality / association | D16: Verified from | E16: Used for
A17: Parent Company | B17: Operating Company | C17: Parent 1→many; child has 0..1 verified parent (where applicable) | D17: Legal/contract confirmation, reviewed group mapping | E17: Corporate group view; don't infer franchise relationship
A18: Operating Company | B18: Workspace | C18: One verified operating Company → many Workspaces; unassigned allowed during review | D18: Contract / CSx or Finance confirmation | E18: CS coverage and consolidated workspace view
A19: Workspace | B19: CB Subscription | C19: One current CB Subscription per sample Workspace; verified product-billing link; preserve historical records. | D19: Backend workspace_id + Chargebee subscription_id | E19: CRM association is a join, not the subscription source of truth.
A20: CB Subscription | B20: Bill-to Company | C20: Bill-to Company is a distinct association role of the existing Company type; payer can equal or differ from operating Company. | D20: Chargebee payer/account data, Finance review | E20: Correct billing vs operating roll-ups
A21: Workspace | B21: User | C21: One Workspace → many Users (membership-specific User records) | D21: Product workspace and user IDs | E21: Active users and seat usage
A22: User | B22: Contact | C22: Many User memberships → one person Contact, when identity verified | D22: Login/person mapping; not name alone | E22: Avoid double counting a person
A23: Buying Company | B23: Deal | C23: One Company → many Sales-led Deals, buyer explicitly recorded | D23: Signed opportunity/contract details | E23: Sales pipeline at correct company level
A24: Deal | B24: Workspace(s) | C24: Explicit optional many-to-many opportunity scope | D24: Deal/contract scope confirmed by AE | E24: No automatic cross-workspace expansions
A26: BEAUTY LOUNGE — WHAT WE CAN AND CANNOT ASSUME
A27: Workspace | B27: Seats | C27: Motion | D27: Operating Company association | E27: Opportunity scope
A28: Beauty Lounge Mitte | B28: 8 | C28: self_signup | D28: Unverified; review first | E28: Not automatically Jonas's
A29: Beauty Lounge Charlottenburg | B29: 6 | C29: self_signup | D29: Unverified; review first | E29: Not automatically Jonas's
A30: Beauty Lounge Spandau | B30: 4 | C30: self_signup | D30: Unverified; review first | E30: Not automatically Jonas's
A31: Beauty Lounge GmbH | B31: 25 | C31: sales_led | D31: Needs validation too | E31: Jonas owns stated AE record; verify Deal scope
A32: Across 4 Workspaces | B32: ='S5 Q1 - CRM gaps'!B13 -> 43 | C32: Licensed seats across sample — not a verified group total | D32: Grouping UNKNOWN | E32: Do not sum group MRR before payer verification
A34: IMPLEMENTATION GUARDRAILS
A35: Identity | B35: Stable workspace/subscription/user IDs; deduplicate by external keys | C35: Avoid email-domain rules to create corporate group | D35: Owner: data + RevOps | E35: Protect existing backend sync
A36: Source of truth | B36: Product backend = usage; Chargebee = authoritative subscriptions/revenue; Stripe = payment evidence; Sales = deal/buying context. | C36: One active subscription counted once, as-of-date reporting | D36: Owner: billing / CRM | E36: No double counted revenue
A37: Validation | B37: Stage unresolved association records for review; record verification status/source and review date | C37: Do not fabricate missing Company links | D37: Owner: Sales/CSx/Finance | E37: Clear unknown vs confirmed
A38: Ownership | B38: Group/account owner can differ from Workspace-level CSx or AE | C38: Use explicit owners/roles; avoid fan-out of tasks | D38: Owner: GTM Ops | E38: Right people see right customer
A39: Pilot | B39: Validate Beauty Lounge relationships with stakeholders, then expand mapping gradually | C39: No bulk merges or new custom object in first release | D39: Owner: RevOps | E39: Minimal risk to live CRM
A41: BOTTOM LINE | B41: Company (parent/operating/bill-to roles) = verified business identities; Workspace = product/risk grain; CB Subscription = Chargebee mirror; User↔Contact = identity; Deal = commercial scope. Diagram embedded in Doc.

Sheet S5 Q3 - safe rollout
A1: SECTION 5 — Q3 | SAFE LIVE CRM MIGRATION
A2: Question | B2: Your redesign has to happen on a live CRM that GTM teams use every day. What would you change first, what would you deliberately leave alone, and what could go wrong in between?
A3: Decision | B3: Audit and validate associations first. Pilot only verified links, compare with the live setup, then roll out in batches with a reversible change log.
A5: ROLL OUT IN CONTROLLED STEPS
A6: Phase | B6: Action | C6: Output / go-no-go check | D6: Owners | E6: Keep working
A7: Week 1 — Inventory | B7: Map current HubSpot association workflows, retries and fallbacks by self-signup, checkout link and partner. Count missing/wrong/duplicate links. | C7: List of workflows, association IDs, exceptions and current reports; snapshot configurations. | D7: RevOps + CRM owner | E7: No edits to production routing or billing
A8: Week 1 — Rules | B8: Define authoritative external IDs AND a single permitted writer per association type; verify operating, payer and Deal scope. Stage unknowns for review. | C8: Writer/role registry + versioned association mapping; gate duplicate legacy branches for pilot records. | D8: RevOps + CSx + Finance + Sales | E8: Preserve working syncs and save previous workflow branches for rapid rollback.
A9: Week 2 — Dry run | B9: Use a sample with Beauty Lounge, SSF, Sales-led and partner/checkout routes. Build read-only comparison mapping. | C9: Review correct Company-to-Workspace links with owners before any write. | D9: RevOps + record owners | E9: Do not trigger customer workflows
A10: Week 2 — Small write pilot | B10: Write only approved links through the assigned writer; shadow/gate conflicting HubSpot fallback branches on pilot records; review diffs. | C10: Subscription totals reconcile, Workspace ownership unchanged, no duplicate CSx tasks. | D10: RevOps + GTM Ops | E10: No second writer for same association type; restore old branch on rollback.
A11: After sign-off — expand | B11: Backfill in small batches, log all changes, publish new group reports only when reconciled. | C11: Explicit approval from Finance/CSx/Sales; stop on mismatch. | D11: RevOps + Finance | E11: Rollback only newly changed associations
A13: CHANGE FIRST VS LEAVE ALONE
A14: Area | B14: Change first | C14: Leave alone | D14: Reason | E14: Validation
A15: Workspace → Company | B15: Populate the existing link only when the operating Company is confirmed. | C15: Workspace product IDs, lifecycle/risk data and product-created records. | D15: Risk alerts remain at Workspace level. | E15: Verified source and reviewer
A16: Company hierarchy | B16: Add parent-child only for confirmed corporate relationships. | C16: Avoid bulk Company merges or domain-based grouping. | D16: Franchise/brand ≠ necessarily common legal parent. | E16: Legal entity evidence
A17: CB Subscription / bill-to | B17: Verify Workspace subscription ID and separate bill-to Company when payer is known. | C17: Backend mirror and Chargebee billing. | D17: No double-counting or wrong payer totals. | E17: Subscription-by-subscription reconciliation
A18: User → Contact | B18: Validate shared login identity across multiple Workspace Users. | C18: Existing User membership and Contact objects. | D18: Shared Contact does not prove ownership. | E18: User + Workspace keys
A19: Deal / Lead | B19: Link buying Company and explicitly in-scope Workspaces for Sales-led Deal. | C19: SSF signup flow; existing Lead & Deal creation. | D19: Avoid assigning Jonas all related-looking accounts. | E19: AE confirmation of Deal scope
A20: Association workflows | B20: Assign one writer per association type; keep fallback workflows in shadow/read-only on pilot records, or disable only their conflicting write branches. | C20: Keep working creation and unrelated retry paths; snapshot configuration before gating. | D20: Prevents last-writer-wins overwrites, loops and association churn. | E20: Track writer/version, association history, retries and orphan/duplicate rates.
A22: WHAT COULD FAIL AND HOW I'D CATCH IT
A23: Failure mode | B23: User/business impact | C23: Early check | D23: Immediate containment | E23: Recovery
A24: Wrong Company link | B24: Wrong group health and commercial ownership. | C24: Sample records + review exceptions. | D24: Stop mapping writes; suppress group automation. | E24: Restore original association from change log
A25: Workflow race / duplicate links | B25: Existing fallback overwrites mapping; duplicates or orphans. | C25: Unexpected association counts; duplicate IDs; retry spikes. | D25: Stop new association writer and reactivate previous safe branch as appropriate. | E25: Reconcile and replay safe batch
A26: Billing mismatch | B26: Inflated MRR, wrong payer, duplicate renewals. | C26: Compare each subscription ID and Finance totals before/after. | D26: Hide new consolidated report until reconciled. | E26: Recalculate from Chargebee IDs
A27: Wrong CSx task / outreach | B27: Tasks reach wrong owner or account; unwanted customer contact. | C27: Test tasks in a non-live/restricted view and inspect trigger ownership. | D27: Disable new group-triggered tasks/outreach. | E27: Clean tasks and review already-sent communications
A28: Late data / failed association | B28: Records look unlinked; false alerts or wrong ownership. | C28: Freshness and exception dashboard; Dagster/Hightouch sync checks. | D28: Mark UNKNOWN; do not auto-remap from missing data. | E28: Retry once sources catch up
A30: BEAUTY LOUNGE CHECK — NOT PROOF OF A CORPORATE GROUP
A31: Sample Workspaces | B31: ='S5 Q1 - CRM gaps'!B12 -> 4 | C31: Existing separate Workspace records. | D31: Known sample | E31: 4 Workspaces
A32: Licensed seats across sample | B32: ='S5 Q1 - CRM gaps'!B13 -> 43 | C32: Sum of licence seats, not one verified customer's total. | D32: Known sample | E32: 43 seats
A33: Verified operating Companies | B33: Unknown | C33: Sales/CSx/Finance must confirm relationship. | D33: Pending | E33: Do not assume one parent Company
A34: Verified bill-to Companies | B34: Unknown | C34: Billing data / Finance must confirm payer. | D34: Pending | E34: Don't aggregate MRR as one payer
A35: Jonas Deal scope | B35: Unknown | C35: AE must confirm exactly which Workspaces are included. | D35: Pending | E35: No automatic expansion assumption
A37: GO / NO-GO BEFORE ROLLOUT
A38: Pilot requirements | B38: Verified Company/payer identity; single writer per association type; old/new association audit; reconciled Chargebee IDs; correct owners; no duplicate tasks; rollback rehearsal and GTM sign-off.
A39: First two-week outcome | B39: Association map, failure baseline, write-ownership design, gated Beauty Lounge pilot, reconciliation, approval and rollback path.
A40: Working note | B40: What I would check with access: HubSpot association workflow branches, retry logs, custom association labels, Chargebee customer IDs and the real Beauty Lounge contract hierarchy.

Sheet S6 Q1 - semantic drift
A1: SECTION 6 — Q1 | SEMANTIC EVENT DRIFT (OPTIONAL)
A2: Question | B2: Trace what this does to your system — the signal, the flags, the actions. Where does the damage land first, who feels it, and after how long?
A3: Scenario | B3: Automatic channel updates migrate affected workflows for three weeks. Each migration emits workflow_edited despite no customer action. Syncs remain green.
A4: Key distinction | B4: If Section 4 uses confirmed successful executions, these edits should not affect risk or actions. A leftover last-edit proxy, dashboard or suppression rule is vulnerable.
A6: TRACE THE FAILURE THROUGH THE STACK
A7: Order | B7: Where | C7: What changes | D7: When (proposed S4 cadence) | E7: Business consequence
A8: 1 | B8: Product backend | C8: System migration fires valid workflow_edited. The event's meaning now includes non-user work. | D8: As channel changes occur over 3 weeks | E8: Raw event stream becomes misleading if treated as user activity
A9: 2 | B9: Warehouse + Dagster | C9: Naive last-edit/last-activity timestamp refreshes; a derived WATCH may clear or be delayed. | D9: Next daily model after ingestion | E9: First incorrect business classification, if proxy used
A10: 3 | B10: Hightouch → HubSpot Workspace | C10: Wrong WATCH/AT RISK status or reason may sync, subject to other independent signals. | D10: Next daily reverse-ETL after model | E10: GTM sees fewer accounts apparently needing help
A11: 4 | B11: HubSpot → Make/n8n | C11: Property-change actions may close/suppress tasks or lifecycle nudges; depends on trigger logic. | D11: Shortly after CRM update | E11: Less intervention for genuinely struggling accounts
A12: 5 | B12: CSx + lifecycle teams | C12: Follow-up queues and SSF guidance opportunities shrink incorrectly. | D12: Same / following day | E12: Teams trust a false sense of improvement
A13: 6 | B13: Customers / outcomes | C13: Customers may miss support; effects on retention or adoption can emerge later. | D13: Days to weeks; effects persist after 3 weeks | E13: Business loss can lag well behind valid green syncs
A15: DESIGN INTENT VS PROXY FAILURE
A16: Implementation | B16: Impact of automatic edits | C16: Why | D16: Requirement | E16: Caveat
A17: Intended S4 risk signal | B17: NO: properly implemented risk and CRM actions do not change from edits alone. | C17: Use successful workflow/AI executions as evidence of use | D17: Separate actor/system edits from success telemetry | E17: Independent billing/failure signals still apply
A18: Stopgap last-edit proxy | B18: POSSIBLE FALSE HEALTH | C18: Background system edits update apparent recency without proving customer engagement. | D18: Treat proxy as low-confidence; exclude system activity | E18: Not every at-risk flag necessarily disappears
A19: Infrastructure status | B19: ALL GREEN | C19: Event schema valid and ingestion/transformation/sync succeed | D19: Semantic QA, not only pipeline health | E19: A high event count is not higher adoption
A21: ILLUSTRATIVE ACCOUNT A CHECK — DAY 40 MIGRATION IS HYPOTHETICAL
A22: Variable | B22: Day / result | C22: Definition / example | D22: Status
A23: Last recorded workflow edit | B23: 19 | C23: Observed workflow_edited on day 19; event extract does NOT identify the actor. | D23: Observed
A24: Automatic system migration | B24: 40 | C24: Example only — NOT asserted to have happened to Account A | D24: Hypothetical
A25: Evaluation day | B25: 41 | C25: One day after hypothetical migration | D25: Hypothetical
A26: Candidate threshold (days) | B26: 14 | C26: Proposed watch threshold to test (not established truth) | D26: Design hypothesis
A27: Naive days since last edit | B27: =B25-B24 -> 1 | C27: Day 41 - automatic day 40 = 1 | D27: Calculated
A28: Days since earlier recorded edit | B28: =B25-B23 -> 22 | C28: Day 41 - day 19 = 22. Not necessarily a user edit. | D28: Calculated
A29: Naive edit-based watch? | B29: =IF(B27>=B26,"WATCH","NO WATCH") -> NO WATCH | C29: False 'NO WATCH' from contaminated proxy | D29: Illustrative
A30: Proxy watch without example migration? | B30: =IF(B28>=B26,"WATCH","NO WATCH") -> WATCH | C30: WATCH from an edit-based proxy alone; NOT confirmed workflow inactivity. | D30: Illustrative
A31: Days of apparent freshness invented | B31: =B28-B27 -> 21
A33: WHAT I WOULD CHECK FIRST
A34: Semantic check | B34: Compare edit spike vs successful workflow executions and deployment history; inspect actor/origin and every use in warehouse models, dashboards, HubSpot flags and Make/n8n suppression rules. | C34: If event origin cannot be distinguished, mark edit-based engagement proxy UNTRUSTED.
A35: Who is affected | B35: Workspaces where risk_status, reason or last_activity changed after automatic edits; downstream task/outreach suppressions. | C35: Do not assume every migrated Workspace became false healthy.
A36: Key takeaway | B36: Correct S4 model: no risk change. Residual edit-based dependencies: potentially false health, even with all technical syncs green. | C36: The timing is next daily model and CRM sync, with effects accumulating across 3 weeks.

Sheet S6 Q2 - incident cleanup
A1: SECTION 6 — Q2 | INCIDENT CLEANUP + CHEAP REPLAY
A2: Question | B2: Three weeks pass before anyone notices. Walk through the cleanup: what do you recompute, what do you do about actions your system already took on the wrong accounts, and how do you handle it when full re-ingestion is expensive?
A3: Core distinction | B3: The correctly implemented execution-based Section 4 model should be unaffected by automatic edits. Recompute only dependencies that still misinterpret workflow_edited as human engagement, and review their downstream actions.
A5: WHAT COULD HAVE BEEN CORRUPTED
A6: Path | B6: What to check | C6: Likely correction | D6: Do not assume | E6: Evidence source
A7: Confirmed execution-based risk | B7: Successful workflow/AI runs, independent message and billing signals | C7: Often no correction required | D7: That every migrated account is false healthy | E7: Warehouse daily snapshots + raw runs
A8: Temporary last-edit activity proxy | B8: Recent activity, candidate WATCH, risk reasons, recovered states | C8: Exclude system edits; reclassify affected decisions | D8: That a creation/edit event proves a workflow ran | E8: Raw product events + migration log
A9: Unknown actor/origin | B9: Edits that cannot be attributed to user or system | C9: Mark edit-based engagement UNKNOWN; no automatic outreach | D9: That time coincidence proves an event is system-originated | E9: Engineering source / deployment metadata
A11: RECOVERY RUNBOOK (ORDER MATTERS)
A12: Step | B12: Action | C12: Output / evidence | D12: Owner / timing | E12: Why
A13: 1. Contain | B13: Pause edit-dependent rules, status changes and outbound automation; leave independent signals live | C13: Paused trigger inventory; communication to CSx/lifecycle | D13: RevOps + GTM Ops; immediately | E13: Prevent new wrong decisions without full outage
A14: 2. Snapshot | B14: Preserve raw events, current/historical risk scores, Dagster runs, Hightouch writes and HubSpot action history | C14: Immutable baseline and audit log | D14: Data + RevOps | E14: Needed for diff and rollback
A15: 3. Classify edits | B15: Get deployment boundary/job IDs; match by event_id, workflow_id, workspace_id and actor/origin if present | C15: Versioned event correction/exclusion table | D15: Engineering + data | E15: Do not delete raw history
A16: 4. Recompute | B16: Replay impacted daily partitions with pre-incident lookback AND post-incident tail until contaminated edits no longer affect rolling metrics or risk status. | C16: Corrected daily Workspace status/reason, valid as-of dates, model version; post-incident carryover checked. | D16: Dagster + warehouse | E16: Don't stop at the final migration date—false recency may persist within later windows.
A17: 5. Diff | B17: Compare before/after daily WATCH/AT RISK/RECOVERED and action eligibility; identify accounts actually impacted | C17: Affected Workspace IDs and exact days; confidence/unknown flags | D17: RevOps + CSx review | E17: Don't assume every edit changed a score
A18: 6. Reconcile actions | B18: Join corrected decisions to HubSpot properties, CSx tasks, sent or suppressed emails, Make/n8n logs | C18: Action repair ledger: missed / closed / unnecessary / no impact | D18: RevOps + Lifecycle | E18: Restore business decisions as well as data
A19: 7. Repair selectively | B19: After a current live check, restore legitimate tasks or approve outreach; handle material wrong sends with owner | C19: Approved current-state fixes, no duplicates | D19: Assigned CSx or lifecycle owner | E19: Old actions may no longer make sense
A20: 8. QA and resume | B20: Reconcile rows and effects; sign off; enable modified triggers gradually | C20: Validation, monitored restart and rollback plan | D20: Data + GTM owners | E20: Prove corrected semantics and outcomes
A22: CUSTOMER-ACTION REPAIR LEDGER
A23: Finding | B23: What happened | C23: Current-state repair | D23: Eligibility / safety check | E23: Audit trail
A24: Missed help | B24: Risk falsely cleared; CSx task or SSF step never created | C24: Re-evaluate TODAY and, if still eligible, create one approved follow-up | D24: Still paid, at risk, correct owner, not opted out | E24: Missed intervention window + recovery action
A25: Task wrongly closed/snoozed | B25: System edit looked like recovered usage | C25: Reopen or replace only when still relevant and owner approves | D25: No existing active task; check new activity | E25: Original task ID and reason
A26: Unnecessary message sent | B26: Unexpected outreach from a bad status or a downstream misuse of edits | C26: Can't unsend; owner reviews whether an explanation is warranted | D26: No automated apology; consider impact | E26: Campaign, recipient, time, reviewer
A27: No change | B27: Migration event had no impact on execution-based model or action | C27: Leave Workspace untouched; record as unaffected | D27: No action | E27: Control cohort for comparison
A29: TARGETED REPLAY — NO FULL AIRBYTE RESYNC
A30: Item | B30: Days / mechanism | C30: Description | D30: Status
A31: Affected incident window (days) | B31: 21 | C31: Three weeks of automatic migrations in the scenario | D31: Source
A32: Example rolling lookback (days) | B32: 14 | C32: Section 4 proposed comparison period; include metric-specific history | D32: Design
A33: Minimum illustrative raw scan window (days) | B33: =B31+B32 -> 35 | C33: Lookback before incident + incident span; may need earlier valid-event history | D33: Calculated
A34: Important boundary | B34: 35 days (21 incident + 14 prior) is a minimum illustrative base, NOT the full replay period. Add the post-incident tail until no affected signal remains; extend further for last-valid-activity or billing dependencies.
A35: Existing warehouse raw data | B35: Keep warehouse raw events immutable; use a correction map and rerun only affected Dagster/warehouse partitions in an isolated dry replay with Hightouch and all customer-facing automations OFF. | C35: Historical recomputation has no customer-facing side effects; no Airbyte charge for existing raw events.
A36: If raw evidence is missing | B36: Request source-specific export or bounded incremental Airbyte backfill (validated cursor), not expensive full resync. | C36: Only the missing source/date/workspaces
A37: Reverse ETL repair | B37: After corrected historical results are validated, use Hightouch to sync only CURRENT, approved Workspace status/reason/evidence. Repair historical misses manually and selectively with eligibility + idempotency checks. | C37: Never stream past state transitions into HubSpot/Make/n8n and accidentally trigger emails or tasks.
A39: RECOVERY SIGN-OFF
